INFO 2023-08-13 10:50:25,314 autoreload:668 Watching for file changes with StatReloader
INFO 2023-08-13 10:51:27,275 autoreload:266 R:\zcx\PyCode\AutoOps\backend\backend\apps\users\urls.py changed, reloading.
INFO 2023-08-13 10:51:27,638 autoreload:668 Watching for file changes with StatReloader
ERROR 2023-08-13 10:51:49,084 log:241 Internal Server Error: /users/login/
Traceback (most recent call last):
  File "R:\zcx\PyCode\AutoOps\venv\lib\site-packages\django\core\handlers\exception.py", line 55, in inner
    response = get_response(request)
  File "R:\zcx\PyCode\AutoOps\venv\lib\site-packages\django\core\handlers\base.py", line 197, in _get_response
    response = wrapped_callback(request, *callback_args, **callback_kwargs)
  File "R:\zcx\PyCode\AutoOps\venv\lib\site-packages\django\views\decorators\csrf.py", line 56, in wrapper_view
    return view_func(*args, **kwargs)
  File "R:\zcx\PyCode\AutoOps\venv\lib\site-packages\django\views\generic\base.py", line 104, in view
    return self.dispatch(request, *args, **kwargs)
  File "R:\zcx\PyCode\AutoOps\venv\lib\site-packages\rest_framework\views.py", line 492, in dispatch
    request = self.initialize_request(request, *args, **kwargs)
  File "R:\zcx\PyCode\AutoOps\venv\lib\site-packages\rest_framework\views.py", line 394, in initialize_request
    authenticators=self.get_authenticators(),
  File "R:\zcx\PyCode\AutoOps\venv\lib\site-packages\rest_framework\views.py", line 272, in get_authenticators
    return [auth() for auth in self.authentication_classes]
TypeError: 'type' object is not iterable
ERROR 2023-08-13 10:51:49,086 basehttp:212 "POST //users/login/ HTTP/1.1" 500 87339
ERROR 2023-08-13 10:52:24,854 log:241 Internal Server Error: /users/login/
Traceback (most recent call last):
  File "R:\zcx\PyCode\AutoOps\venv\lib\site-packages\django\core\handlers\exception.py", line 55, in inner
    response = get_response(request)
  File "R:\zcx\PyCode\AutoOps\venv\lib\site-packages\django\core\handlers\base.py", line 197, in _get_response
    response = wrapped_callback(request, *callback_args, **callback_kwargs)
  File "R:\zcx\PyCode\AutoOps\venv\lib\site-packages\django\views\decorators\csrf.py", line 56, in wrapper_view
    return view_func(*args, **kwargs)
  File "R:\zcx\PyCode\AutoOps\venv\lib\site-packages\django\views\generic\base.py", line 104, in view
    return self.dispatch(request, *args, **kwargs)
  File "R:\zcx\PyCode\AutoOps\venv\lib\site-packages\rest_framework\views.py", line 492, in dispatch
    request = self.initialize_request(request, *args, **kwargs)
  File "R:\zcx\PyCode\AutoOps\venv\lib\site-packages\rest_framework\views.py", line 394, in initialize_request
    authenticators=self.get_authenticators(),
  File "R:\zcx\PyCode\AutoOps\venv\lib\site-packages\rest_framework\views.py", line 272, in get_authenticators
    return [auth() for auth in self.authentication_classes]
TypeError: 'type' object is not iterable
ERROR 2023-08-13 10:52:24,855 basehttp:212 "POST /users/login/ HTTP/1.1" 500 87339
INFO 2023-08-13 10:57:59,241 autoreload:266 R:\zcx\PyCode\AutoOps\backend\backend\apps\users\views.py changed, reloading.
INFO 2023-08-13 10:57:59,586 autoreload:668 Watching for file changes with StatReloader
ERROR 2023-08-13 10:58:03,511 log:241 Internal Server Error: /users/login/
Traceback (most recent call last):
  File "R:\zcx\PyCode\AutoOps\venv\lib\site-packages\django\core\handlers\exception.py", line 55, in inner
    response = get_response(request)
  File "R:\zcx\PyCode\AutoOps\venv\lib\site-packages\django\core\handlers\base.py", line 197, in _get_response
    response = wrapped_callback(request, *callback_args, **callback_kwargs)
  File "R:\zcx\PyCode\AutoOps\venv\lib\site-packages\django\views\decorators\csrf.py", line 56, in wrapper_view
    return view_func(*args, **kwargs)
  File "R:\zcx\PyCode\AutoOps\venv\lib\site-packages\django\views\generic\base.py", line 104, in view
    return self.dispatch(request, *args, **kwargs)
  File "R:\zcx\PyCode\AutoOps\venv\lib\site-packages\rest_framework\views.py", line 492, in dispatch
    request = self.initialize_request(request, *args, **kwargs)
  File "R:\zcx\PyCode\AutoOps\venv\lib\site-packages\rest_framework\views.py", line 394, in initialize_request
    authenticators=self.get_authenticators(),
  File "R:\zcx\PyCode\AutoOps\venv\lib\site-packages\rest_framework\views.py", line 272, in get_authenticators
    return [auth() for auth in self.authentication_classes]
TypeError: 'type' object is not iterable
ERROR 2023-08-13 10:58:03,512 basehttp:212 "POST /users/login/ HTTP/1.1" 500 87339
INFO 2023-08-13 10:59:24,737 autoreload:266 R:\zcx\PyCode\AutoOps\backend\backend\apps\users\urls.py changed, reloading.
INFO 2023-08-13 10:59:25,061 autoreload:668 Watching for file changes with StatReloader
INFO 2023-08-13 10:59:28,589 basehttp:212 "POST /users/login/ HTTP/1.1" 200 483
INFO 2023-08-13 11:10:20,524 basehttp:212 "POST /users/login/ HTTP/1.1" 200 483
INFO 2023-08-13 11:11:58,099 basehttp:212 "OPTIONS /users/login/ HTTP/1.1" 200 0
INFO 2023-08-13 11:11:58,256 basehttp:212 "POST /users/login/ HTTP/1.1" 200 483
INFO 2023-08-13 13:18:36,680 basehttp:212 "OPTIONS /users/login/ HTTP/1.1" 200 0
INFO 2023-08-13 13:18:36,817 basehttp:212 "POST /users/login/ HTTP/1.1" 200 483
INFO 2023-08-13 13:18:53,248 basehttp:212 "OPTIONS /users/login/ HTTP/1.1" 200 0
WARNING 2023-08-13 13:18:53,251 log:241 Bad Request: /users/login/
WARNING 2023-08-13 13:18:53,251 basehttp:212 "POST /users/login/ HTTP/1.1" 400 81
INFO 2023-08-13 13:18:56,083 basehttp:212 "OPTIONS /users/login/ HTTP/1.1" 200 0
INFO 2023-08-13 13:18:56,218 basehttp:212 "POST /users/login/ HTTP/1.1" 200 483
